Traceback (most recent call last):
  File "/usr/local/lib/python3.10/site-packages/ray/_private/gcs_utils.py", line 123, in check_health
    resp = stub.CheckAlive(req, timeout=timeout)
  File "/usr/local/lib/python3.10/site-packages/grpc/_channel.py", line 946, in __call__
    return _end_unary_response_blocking(state, call, False, None)
  File "/usr/local/lib/python3.10/site-packages/grpc/_channel.py", line 849, in _end_unary_response_blocking
    raise _InactiveRpcError(state)
grpc._channel._InactiveRpcError: <_InactiveRpcError of RPC that terminated with:
	status = StatusCode.UNAVAILABLE
	details = "failed to connect to all addresses; last error: UNKNOWN: ipv4:172.17.0.2:62644: Failed to connect to remote host: Connection refused"
	debug_error_string = "UNKNOWN:failed to connect to all addresses; last error: UNKNOWN: ipv4:172.17.0.2:62644: Failed to connect to remote host: Connection refused {grpc_status:14, created_time:"2023-07-02T18:13:48.379313417+00:00"}"
>
/usr/local/lib/python3.10/site-packages/ray/dashboard/dashboard.py:236: DeprecationWarning: The 'warn' method is deprecated, use 'warning' instead
  logger.warn("Exiting with SIGTERM immediately...")
